Traceback (most recent call last):
  File "/opt/hostedtoolcache/Python/3.8.6/x64/lib/python3.8/site-packages/jupyter_cache/executors/utils.py", line 51, in single_nb_execution
    executenb(
  File "/opt/hostedtoolcache/Python/3.8.6/x64/lib/python3.8/site-packages/nbclient/client.py", line 1087, in execute
    return NotebookClient(nb=nb, resources=resources, km=km, **kwargs).execute()
  File "/opt/hostedtoolcache/Python/3.8.6/x64/lib/python3.8/site-packages/nbclient/util.py", line 74, in wrapped
    return just_run(coro(*args, **kwargs))
  File "/opt/hostedtoolcache/Python/3.8.6/x64/lib/python3.8/site-packages/nbclient/util.py", line 53, in just_run
    return loop.run_until_complete(coro)
  File "/opt/hostedtoolcache/Python/3.8.6/x64/lib/python3.8/asyncio/base_events.py", line 616, in run_until_complete
    return future.result()
  File "/opt/hostedtoolcache/Python/3.8.6/x64/lib/python3.8/site-packages/nbclient/client.py", line 540, in async_execute
    await self.async_execute_cell(
  File "/opt/hostedtoolcache/Python/3.8.6/x64/lib/python3.8/site-packages/nbclient/client.py", line 832, in async_execute_cell
    self._check_raise_for_error(cell, exec_reply)
  File "/opt/hostedtoolcache/Python/3.8.6/x64/lib/python3.8/site-packages/nbclient/client.py", line 740, in _check_raise_for_error
    raise CellExecutionError.from_cell_and_msg(cell, exec_reply['content'])
nbclient.exceptions.CellExecutionError: An error occurred while executing the following cell:
------------------
ax.plot(sol.y_events[2][:, 0], np.zeros(1367), 'ro', fillstyle='none')
------------------

[0;31m---------------------------------------------------------------------------[0m
[0;31mValueError[0m                                Traceback (most recent call last)
[0;32m<ipython-input-8-f921d1aaec33>[0m in [0;36m<module>[0;34m[0m
[0;32m----> 1[0;31m [0max[0m[0;34m.[0m[0mplot[0m[0;34m([0m[0msol[0m[0;34m.[0m[0my_events[0m[0;34m[[0m[0;36m2[0m[0;34m][0m[0;34m[[0m[0;34m:[0m[0;34m,[0m [0;36m0[0m[0;34m][0m[0;34m,[0m [0mnp[0m[0;34m.[0m[0mzeros[0m[0;34m([0m[0;36m1367[0m[0;34m)[0m[0;34m,[0m [0;34m'ro'[0m[0;34m,[0m [0mfillstyle[0m[0;34m=[0m[0;34m'none'[0m[0;34m)[0m[0;34m[0m[0;34m[0m[0m
[0m
[0;32m/opt/hostedtoolcache/Python/3.8.6/x64/lib/python3.8/site-packages/matplotlib/axes/_axes.py[0m in [0;36mplot[0;34m(self, scalex, scaley, data, *args, **kwargs)[0m
[1;32m   1741[0m         """
[1;32m   1742[0m         [0mkwargs[0m [0;34m=[0m [0mcbook[0m[0;34m.[0m[0mnormalize_kwargs[0m[0;34m([0m[0mkwargs[0m[0;34m,[0m [0mmlines[0m[0;34m.[0m[0mLine2D[0m[0;34m)[0m[0;34m[0m[0;34m[0m[0m
[0;32m-> 1743[0;31m         [0mlines[0m [0;34m=[0m [0;34m[[0m[0;34m*[0m[0mself[0m[0;34m.[0m[0m_get_lines[0m[0;34m([0m[0;34m*[0m[0margs[0m[0;34m,[0m [0mdata[0m[0;34m=[0m[0mdata[0m[0;34m,[0m [0;34m**[0m[0mkwargs[0m[0;34m)[0m[0;34m][0m[0;34m[0m[0;34m[0m[0m
[0m[1;32m   1744[0m         [0;32mfor[0m [0mline[0m [0;32min[0m [0mlines[0m[0;34m:[0m[0;34m[0m[0;34m[0m[0m
[1;32m   1745[0m             [0mself[0m[0;34m.[0m[0madd_line[0m[0;34m([0m[0mline[0m[0;34m)[0m[0;34m[0m[0;34m[0m[0m

[0;32m/opt/hostedtoolcache/Python/3.8.6/x64/lib/python3.8/site-packages/matplotlib/axes/_base.py[0m in [0;36m__call__[0;34m(self, data, *args, **kwargs)[0m
[1;32m    271[0m                 [0mthis[0m [0;34m+=[0m [0margs[0m[0;34m[[0m[0;36m0[0m[0;34m][0m[0;34m,[0m[0;34m[0m[0;34m[0m[0m
[1;32m    272[0m                 [0margs[0m [0;34m=[0m [0margs[0m[0;34m[[0m[0;36m1[0m[0;34m:[0m[0;34m][0m[0;34m[0m[0;34m[0m[0m
[0;32m--> 273[0;31m             [0;32myield[0m [0;32mfrom[0m [0mself[0m[0;34m.[0m[0m_plot_args[0m[0;34m([0m[0mthis[0m[0;34m,[0m [0mkwargs[0m[0;34m)[0m[0;34m[0m[0;34m[0m[0m
[0m[1;32m    274[0m [0;34m[0m[0m
[1;32m    275[0m     [0;32mdef[0m [0mget_next_color[0m[0;34m([0m[0mself[0m[0;34m)[0m[0;34m:[0m[0;34m[0m[0;34m[0m[0m

[0;32m/opt/hostedtoolcache/Python/3.8.6/x64/lib/python3.8/site-packages/matplotlib/axes/_base.py[0m in [0;36m_plot_args[0;34m(self, tup, kwargs)[0m
[1;32m    397[0m [0;34m[0m[0m
[1;32m    398[0m         [0;32mif[0m [0mx[0m[0;34m.[0m[0mshape[0m[0;34m[[0m[0;36m0[0m[0;34m][0m [0;34m!=[0m [0my[0m[0;34m.[0m[0mshape[0m[0;34m[[0m[0;36m0[0m[0;34m][0m[0;34m:[0m[0;34m[0m[0;34m[0m[0m
[0;32m--> 399[0;31m             raise ValueError(f"x and y must have same first dimension, but "
[0m[1;32m    400[0m                              f"have shapes {x.shape} and {y.shape}")
[1;32m    401[0m         [0;32mif[0m [0mx[0m[0;34m.[0m[0mndim[0m [0;34m>[0m [0;36m2[0m [0;32mor[0m [0my[0m[0;34m.[0m[0mndim[0m [0;34m>[0m [0;36m2[0m[0;34m:[0m[0;34m[0m[0;34m[0m[0m

[0;31mValueError[0m: x and y must have same first dimension, but have shapes (137,) and (1367,)
ValueError: x and y must have same first dimension, but have shapes (137,) and (1367,)

